{"identifier":{"interfaceLanguage":"swift","url":"doc:\/\/RxFireAuth\/documentation\/RxFireAuth\/UserError\/networkError"},"schemaVersion":{"minor":3,"patch":0,"major":0},"kind":"symbol","sections":[],"primaryContentSections":[{"kind":"declarations","declarations":[{"tokens":[{"text":"case","kind":"keyword"},{"text":" ","kind":"text"},{"kind":"identifier","text":"networkError"}],"languages":["swift"],"platforms":["macOS"]}]}],"hierarchy":{"paths":[["doc:\/\/RxFireAuth\/documentation\/RxFireAuth","doc:\/\/RxFireAuth\/documentation\/RxFireAuth\/UserError"]]},"variants":[{"paths":["\/documentation\/rxfireauth\/usererror\/networkerror"],"traits":[{"interfaceLanguage":"swift"}]}],"metadata":{"externalID":"s:10RxFireAuth9UserErrorO07networkE0yA2CmF","role":"symbol","title":"UserError.networkError","fragments":[{"text":"case","kind":"keyword"},{"kind":"text","text":" "},{"kind":"identifier","text":"networkError"}],"modules":[{"name":"RxFireAuth"}],"symbolKind":"case","roleHeading":"Case"},"abstract":[{"type":"text","text":"An error occurred while reaching Firebase servers."}],"references":{"doc://RxFireAuth/documentation/RxFireAuth/UserError":{"role":"symbol","type":"topic","abstract":[{"type":"text","text":"Errors thrown by  "},{"type":"codeVoice","code":"UserManagerType"},{"type":"text","text":" implementations."}],"identifier":"doc:\/\/RxFireAuth\/documentation\/RxFireAuth\/UserError","navigatorTitle":[{"text":"UserError","kind":"identifier"}],"fragments":[{"kind":"keyword","text":"enum"},{"kind":"text","text":" "},{"text":"UserError","kind":"identifier"}],"kind":"symbol","url":"\/documentation\/rxfireauth\/usererror","title":"UserError"},"doc://RxFireAuth/documentation/RxFireAuth":{"identifier":"doc:\/\/RxFireAuth\/documentation\/RxFireAuth","role":"collection","type":"topic","kind":"symbol","title":"RxFireAuth","abstract":[],"url":"\/documentation\/rxfireauth"},"doc://RxFireAuth/documentation/RxFireAuth/UserError/networkError":{"type":"topic","title":"UserError.networkError","kind":"symbol","identifier":"doc:\/\/RxFireAuth\/documentation\/RxFireAuth\/UserError\/networkError","abstract":[{"type":"text","text":"An error occurred while reaching Firebase servers."}],"role":"symbol","fragments":[{"text":"case","kind":"keyword"},{"text":" ","kind":"text"},{"kind":"identifier","text":"networkError"}],"url":"\/documentation\/rxfireauth\/usererror\/networkerror"}}}